Workbook

Sheet Read Me
A1: PPS / Elmiron Platform - Project Tracker
A2: 16-week MVP - 3 developers - v1.0
A4: PROJECT START (Monday of Week 1) | B4: 2026-08-10 | C4: <- EDIT THIS. Every date in the tracker is calculated from it.
A6: STATUS SUMMARY
A7: Total tasks | B7: =COUNTA('Task Tracker'!A2:A200) -> 103
A8: Not Started | B8: =COUNTIF('Task Tracker'!H2:H200,"Not Started") -> 103
A9: In Progress | B9: =COUNTIF('Task Tracker'!H2:H200,"In Progress") -> 0
A10: Blocked | B10: =COUNTIF('Task Tracker'!H2:H200,"Blocked") -> 0
A11: Done | B11: =COUNTIF('Task Tracker'!H2:H200,"Done") -> 0
A12: READY TO START NOW | B12: =COUNTIFS('Task Tracker'!G2:G200,"READY",'Task Tracker'!H2:H200,"Not Started") -> 3
A13: Waiting on a dependency | B13: =COUNTIF('Task Tracker'!G2:G200,"WAITING") -> 100
A14: % Complete | B14: =IFERROR(COUNTIF('Task Tracker'!H2:H200,"Done")/COUNTA('Task Tracker'!A2:A200),0) -> 0
A16: TASKS BY ROLE
A17: Backend | B17: =COUNTIF('Task Tracker'!D2:D200,"Backend")&" tasks / "&COUNTIFS('Task Tracker'!D2:D200,"Backend",'Task Tracker'!H2:H200,"Done")&" done" -> 39 tasks / 0 done
A18: Frontend | B18: =COUNTIF('Task Tracker'!D2:D200,"Frontend")&" tasks / "&COUNTIFS('Task Tracker'!D2:D200,"Frontend",'Task Tracker'!H2:H200,"Done")&" done" -> 33 tasks / 0 done
A19: AI/Data | B19: =COUNTIF('Task Tracker'!D2:D200,"AI/Data")&" tasks / "&COUNTIFS('Task Tracker'!D2:D200,"AI/Data",'Task Tracker'!H2:H200,"Done")&" done" -> 31 tasks / 0 done
A21: HOW TO USE THIS FILE
A22: Task Tracker | C22: The master list. Only edit the Status, Owner and Notes columns. Everything else is calculated.
A23: Can Start? column | C23: Calculated. READY means its dependency is Done. WAITING means it is not. Filter on READY to see what can begin today.
A24: Status dropdown | C24: Not Started / In Progress / Blocked / Done. Setting a task to Done releases everything that depends on it.
A25: Dates | C25: Calculated from the project start date above. Change that one cell and the whole schedule moves.
A26: Timeline | C26: Week-by-week view of who is doing what. Read-only summary.
A27: Gates | C27: Six checkpoints. Do not start the next phase until the gate passes. The reviewer runs the test - never accept a report.
A28: Interfaces | C28: Four contracts between the three roles, with due dates. Miss one and two people stall.
A29: Decisions | C29: Locked decisions and open blockers. O1 and O2 are blocking work right now.
A30: Risks | C30: Ranked. Owner named. Review weekly.
A31: Cut Order | C31: Agreed in advance. When the schedule slips, cut from the top. Never negotiate this in the moment.
A33: EDIT ONLY THESE | C33: Yellow = you edit. Everything else is a formula - overwriting it breaks the tracker.

Sheet Task Tracker
A1: ID | B1: Week | C1: Phase | D1: Role | E1: Task | F1: Depends On | G1: Can Start? | H1: Status | I1: Owner | J1: Start | K1: Due | L1: Notes
A2: BE-01 | B2: 1 | C2: P0 Foundations | D2: Backend | E2: Monorepo: Turborepo + pnpm workspaces, strict TS, lint/format | F2: — | G2: =IF($F2="—","READY",IF(IFERROR(INDEX($H$2:$H$200,MATCH($F2,$A$2:$A$200,0)),"")="Done","READY","WAITING")) -> READY | H2: Not Started | J2: ='Read Me'!$B$4+($B2-1)*7 -> 46244 | K2: =J2+6 -> 46250
A3: BE-02 | B3: 1 | C3: P0 Foundations | D3: Backend | E3: CI/CD: GitHub Actions - typecheck, lint, tests on every PR | F3: BE-01 | G3: =IF($F3="—","READY",IF(IFERROR(INDEX($H$2:$H$200,MATCH($F3,$A$2:$A$200,0)),"")="Done","READY","WAITING")) -> WAITING | H3: Not Started | J3: ='Read Me'!$B$4+($B3-1)*7 -> 46244 | K3: =J3+6 -> 46250
A4: BE-03 | B4: 1 | C4: P0 Foundations | D4: Backend | E4: Two Supabase projects: Mumbai + US. Same migrations, separate data. | F4: — | G4: =IF($F4="—","READY",IF(IFERROR(INDEX($H$2:$H$200,MATCH($F4,$A$2:$A$200,0)),"")="Done","READY","WAITING")) -> READY | H4: Not Started | J4: ='Read Me'!$B$4+($B4-1)*7 -> 46244 | K4: =J4+6 -> 46250 | L4: Never one multi-region DB
A5: BE-04 | B5: 1 | C5: P0 Foundations | D5: Backend | E5: Auth + 9 roles + user_profiles table | F5: BE-03 | G5: =IF($F5="—","READY",IF(IFERROR(INDEX($H$2:$H$200,MATCH($F5,$A$2:$A$200,0)),"")="Done","READY","WAITING")) -> WAITING | H5: Not Started | J5: ='Read Me'!$B$4+($B5-1)*7 -> 46244 | K5: =J5+6 -> 46250
A6: BE-05 | B6: 1 | C6: P0 Foundations | D6: Backend | E6: PUBLISH packages/core types (contract I1) | F6: BE-04 | G6: =IF($F6="—","READY",IF(IFERROR(INDEX($H$2:$H$200,MATCH($F6,$A$2:$A$200,0)),"")="Done","READY","WAITING")) -> WAITING | H6: Not Started | J6: ='Read Me'!$B$4+($B6-1)*7 -> 46244 | K6: =J6+6 -> 46250 | L6: DUE FRI W1 - frontend blocked without it
A7: FE-01 | B7: 1 | C7: P0 Foundations | D7: Frontend | E7: Expo scaffold + Expo Router inside the monorepo | F7: BE-01 | G7: =IF($F7="—","READY",IF(IFERROR(INDEX($H$2:$H$200,MATCH($F7,$A$2:$A$200,0)),"")="Done","READY","WAITING")) -> WAITING | H7: Not Started | J7: ='Read Me'!$B$4+($B7-1)*7 -> 46244 | K7: =J7+6 -> 46250
A8: FE-02 | B8: 1 | C8: P0 Foundations | D8: Frontend | E8: Next.js App Router scaffold | F8: BE-01 | G8: =IF($F8="—","READY",IF(IFERROR(INDEX($H$2:$H$200,MATCH($F8,$A$2:$A$200,0)),"")="Done","READY","WAITING")) -> WAITING | H8: Not Started | J8: ='Read Me'!$B$4+($B8-1)*7 -> 46244 | K8: =J8+6 -> 46250
A9: FE-03 | B9: 1 | C9: P0 Foundations | D9: Frontend | E9: Token pipeline: design-tokens.json to Tailwind + RN theme | F9: FE-02 | G9: =IF($F9="—","READY",IF(IFERROR(INDEX($H$2:$H$200,MATCH($F9,$A$2:$A$200,0)),"")="Done","READY","WAITING")) -> WAITING | H9: Not Started | J9: ='Read Me'!$B$4+($B9-1)*7 -> 46244 | K9: =J9+6 -> 46250 | L9: Needs design D1
A10: AI-01 | B10: 1 | C10: P0 Foundations | D10: AI/Data | E10: Data model design review with Backend | F10: — | G10: =IF($F10="—","READY",IF(IFERROR(INDEX($H$2:$H$200,MATCH($F10,$A$2:$A$200,0)),"")="Done","READY","WAITING")) -> READY | H10: Not Started | J10: ='Read Me'!$B$4+($B10-1)*7 -> 46244 | K10: =J10+6 -> 46250 | L10: Can start day 1 alongside Backend
A11: AI-02 | B11: 1 | C11: P0 Foundations | D11: AI/Data | E11: Analytics event schema definition | F11: AI-01 | G11: =IF($F11="—","READY",IF(IFERROR(INDEX($H$2:$H$200,MATCH($F11,$A$2:$A$200,0)),"")="Done","READY","WAITING")) -> WAITING | H11: Not Started | J11: ='Read Me'!$B$4+($B11-1)*7 -> 46244 | K11: =J11+6 -> 46250 | L11: Get it right now - retrofit is expensive
A12: BE-06 | B12: 2 | C12: P0 Foundations | D12: Backend | E12: Commercial schema: orgs, territories, doctors, visits, beat plans, content | F12: BE-04 | G12: =IF($F12="—","READY",IF(IFERROR(INDEX($H$2:$H$200,MATCH($F12,$A$2:$A$200,0)),"")="Done","READY","WAITING")) -> WAITING | H12: Not Started | J12: ='Read Me'!$B$4+($B12-1)*7 -> 46251 | K12: =J12+6 -> 46257
A13: BE-07 | B13: 2 | C13: P0 Foundations | D13: Backend | E13: Clinical schema namespace + placeholder patients table ONLY | F13: BE-06 | G13: =IF($F13="—","READY",IF(IFERROR(INDEX($H$2:$H$200,MATCH($F13,$A$2:$A$200,0)),"")="Done","READY","WAITING")) -> WAITING | H13: Not Started | J13: ='Read Me'!$B$4+($B13-1)*7 -> 46251 | K13: =J13+6 -> 46257 | L13: Deliberately incomplete - do not guess ahead
A14: BE-08 | B14: 2 | C14: P0 Foundations | D14: Backend | E14: Row-level security policies for all 9 roles | F14: BE-07 | G14: =IF($F14="—","READY",IF(IFERROR(INDEX($H$2:$H$200,MATCH($F14,$A$2:$A$200,0)),"")="Done","READY","WAITING")) -> WAITING | H14: Not Started | J14: ='Read Me'!$B$4+($B14-1)*7 -> 46251 | K14: =J14+6 -> 46257 | L14: THE core deliverable
A15: BE-09 | B15: 2 | C15: P0 Foundations | D15: Backend | E15: Audit log: DB triggers, append-only, logs reads not just writes | F15: BE-08 | G15: =IF($F15="—","READY",IF(IFERROR(INDEX($H$2:$H$200,MATCH($F15,$A$2:$A$200,0)),"")="Done","READY","WAITING")) -> WAITING | H15: Not Started | J15: ='Read Me'!$B$4+($B15-1)*7 -> 46251 | K15: =J15+6 -> 46257
A16: BE-10 | B16: 2 | C16: P0 Foundations | D16: Backend | E16: Consent data model - immutable, withdrawal is a new row | F16: BE-08 | G16: =IF($F16="—","READY",IF(IFERROR(INDEX($H$2:$H$200,MATCH($F16,$A$2:$A$200,0)),"")="Done","READY","WAITING")) -> WAITING | H16: Not Started | J16: ='Read Me'!$B$4+($B16-1)*7 -> 46251 | K16: =J16+6 -> 46257
A17: BE-11 | B17: 2 | C17: P0 Foundations | D17: Backend | E17: MOCK SERVER running with fixtures (contract I2) | F17: BE-05 | G17: =IF($F17="—","READY",IF(IFERROR(INDEX($H$2:$H$200,MATCH($F17,$A$2:$A$200,0)),"")="Done","READY","WAITING")) -> WAITING | H17: Not Started | J17: ='Read Me'!$B$4+($B17-1)*7 -> 46251 | K17: =J17+6 -> 46257 | L17: DUE END W2 - highest-value unblocker
A18: BE-12 | B18: 2 | C18: P0 Foundations | D18: Backend | E18: Adversarial RLS test suite - 15 attack paths must all fail | F18: BE-08 | G18: =IF($F18="—","READY",IF(IFERROR(INDEX($H$2:$H$200,MATCH($F18,$A$2:$A$200,0)),"")="Done","READY","WAITING")) -> WAITING | H18: Not Started | J18: ='Read Me'!$B$4+($B18-1)*7 -> 46251 | K18: =J18+6 -> 46257 | L18: Gate 0 evidence
A19: FE-04 | B19: 2 | C19: P0 Foundations | D19: Frontend | E19: Shell navigation both platforms | F19: FE-03 | G19: =IF($F19="—","READY",IF(IFERROR(INDEX($H$2:$H$200,MATCH($F19,$A$2:$A$200,0)),"")="Done","READY","WAITING")) -> WAITING | H19: Not Started | J19: ='Read Me'!$B$4+($B19-1)*7 -> 46251 | K19: =J19+6 -> 46257
A20: FE-05 | B20: 2 | C20: P0 Foundations | D20: Frontend | E20: Layout primitives + component library wiring | F20: FE-04 | G20: =IF($F20="—","READY",IF(IFERROR(INDEX($H$2:$H$200,MATCH($F20,$A$2:$A$200,0)),"")="Done","READY","WAITING")) -> WAITING | H20: Not Started | J20: ='Read Me'!$B$4+($B20-1)*7 -> 46251 | K20: =J20+6 -> 46257 | L20: Needs design D2
A21: FE-06 | B21: 2 | C21: P0 Foundations | D21: Frontend | E21: Connect to mock server end to end | F21: BE-11 | G21: =IF($F21="—","READY",IF(IFERROR(INDEX($H$2:$H$200,MATCH($F21,$A$2:$A$200,0)),"")="Done","READY","WAITING")) -> WAITING | H21: Not Started | J21: ='Read Me'!$B$4+($B21-1)*7 -> 46251 | K21: =J21+6 -> 46257 | L21: Do NOT build screens yet
A22: AI-03 | B22: 2 | C22: P0 Foundations | D22: AI/Data | E22: Audit log capture design review | F22: AI-02 | G22: =IF($F22="—","READY",IF(IFERROR(INDEX($H$2:$H$200,MATCH($F22,$A$2:$A$200,0)),"")="Done","READY","WAITING")) -> WAITING | H22: Not Started | J22: ='Read Me'!$B$4+($B22-1)*7 -> 46251 | K22: =J22+6 -> 46257
A23: AI-04 | B23: 2 | C23: P0 Foundations | D23: AI/Data | E23: Seed + test data generator (deterministic, re-runnable) | F23: AI-02 | G23: =IF($F23="—","READY",IF(IFERROR(INDEX($H$2:$H$200,MATCH($F23,$A$2:$A$200,0)),"")="Done","READY","WAITING")) -> WAITING | H23: Not Started | J23: ='Read Me'!$B$4+($B23-1)*7 -> 46251 | K23: =J23+6 -> 46257 | L23: Gate 0 test suite needs this
A24: BE-13 | B24: 3 | C24: P1 Commercial | D24: Backend | E24: Doctor, territory, beat-plan APIs | F24: BE-12 | G24: =IF($F24="—","READY",IF(IFERROR(INDEX($H$2:$H$200,MATCH($F24,$A$2:$A$200,0)),"")="Done","READY","WAITING")) -> WAITING | H24: Not Started | J24: ='Read Me'!$B$4+($B24-1)*7 -> 46258 | K24: =J24+6 -> 46264
A25: BE-14 | B25: 3 | C25: P1 Commercial | D25: Backend | E25: Geo check-in/out API with work-hours enforcement | F25: BE-13 | G25: =IF($F25="—","READY",IF(IFERROR(INDEX($H$2:$H$200,MATCH($F25,$A$2:$A$200,0)),"")="Done","READY","WAITING")) -> WAITING | H25: Not Started | J25: ='Read Me'!$B$4+($B25-1)*7 -> 46258 | K25: =J25+6 -> 46264 | L25: Hard stop outside shift window
A26: BE-15 | B26: 3 | C26: P1 Commercial | D26: Backend | E26: Aggregation contract I3 published to AI/Data | F26: BE-12 | G26: =IF($F26="—","READY",IF(IFERROR(INDEX($H$2:$H$200,MATCH($F26,$A$2:$A$200,0)),"")="Done","READY","WAITING")) -> WAITING | H26: Not Started | J26: ='Read Me'!$B$4+($B26-1)*7 -> 46258 | K26: =J26+6 -> 46264 | L26: Compliance artifact - get it reviewed
A27: FE-07 | B27: 3 | C27: P1 Commercial | D27: Frontend | E27: Field app: MR day flow shell + beat plan + today | F27: FE-06 | G27: =IF($F27="—","READY",IF(IFERROR(INDEX($H$2:$H$200,MATCH($F27,$A$2:$A$200,0)),"")="Done","READY","WAITING")) -> WAITING | H27: Not Started | J27: ='Read Me'!$B$4+($B27-1)*7 -> 46258 | K27: =J27+6 -> 46264 | L27: Needs design D3
A28: FE-08 | B28: 3 | C28: P1 Commercial | D28: Frontend | E28: Field app: geo check-in / check-out screens | F28: FE-07 | G28: =IF($F28="—","READY",IF(IFERROR(INDEX($H$2:$H$200,MATCH($F28,$A$2:$A$200,0)),"")="Done","READY","WAITING")) -> WAITING | H28: Not Started | J28: ='Read Me'!$B$4+($B28-1)*7 -> 46258 | K28: =J28+6 -> 46264 | L28: One tap from doctor screen
A29: AI-05 | B29: 3 | C29: P1 Commercial | D29: AI/Data | E29: Anonymised aggregation service | F29: BE-15 | G29: =IF($F29="—","READY",IF(IFERROR(INDEX($H$2:$H$200,MATCH($F29,$A$2:$A$200,0)),"")="Done","READY","WAITING")) -> WAITING | H29: Not Started | J29: ='Read Me'!$B$4+($B29-1)*7 -> 46258 | K29: =J29+6 -> 46264 | L29: ONLY bridge across the boundary
A30: AI-06 | B30: 3 | C30: P1 Commercial | D30: AI/Data | E30: Suppression logic - any cell under 5 patients renders as dash | F30: AI-05 | G30: =IF($F30="—","READY",IF(IFERROR(INDEX($H$2:$H$200,MATCH($F30,$A$2:$A$200,0)),"")="Done","READY","WAITING")) -> WAITING | H30: Not Started | J30: ='Read Me'!$B$4+($B30-1)*7 -> 46258 | K30: =J30+6 -> 46264 | L30: No join key back to an individual
A31: BE-16 | B31: 4 | C31: P1 Commercial | D31: Backend | E31: Offline sync protocol | F31: BE-13 | G31: =IF($F31="—","READY",IF(IFERROR(INDEX($H$2:$H$200,MATCH($F31,$A$2:$A$200,0)),"")="Done","READY","WAITING")) -> WAITING | H31: Not Started | J31: ='Read Me'!$B$4+($B31-1)*7 -> 46265 | K31: =J31+6 -> 46271
A32: BE-17 | B32: 4 | C32: P1 Commercial | D32: Backend | E32: Sync conflict resolution + queue semantics | F32: BE-16 | G32: =IF($F32="—","READY",IF(IFERROR(INDEX($H$2:$H$200,MATCH($F32,$A$2:$A$200,0)),"")="Done","READY","WAITING")) -> WAITING | H32: Not Started | J32: ='Read Me'!$B$4+($B32-1)*7 -> 46265 | K32: =J32+6 -> 46271
A33: FE-09 | B33: 4 | C33: P1 Commercial | D33: Frontend | E33: Field app: call report screen | F33: FE-08 | G33: =IF($F33="—","READY",IF(IFERROR(INDEX($H$2:$H$200,MATCH($F33,$A$2:$A$200,0)),"")="Done","READY","WAITING")) -> WAITING | H33: Not Started | J33: ='Read Me'!$B$4+($B33-1)*7 -> 46265 | K33: =J33+6 -> 46271 | L33: MUST be completable in under 60 seconds
A34: FE-10 | B34: 4 | C34: P1 Commercial | D34: Frontend | E34: Field app: offline UI + sync state + queue visibility | F34: FE-09 | G34: =IF($F34="—","READY",IF(IFERROR(INDEX($H$2:$H$200,MATCH($F34,$A$2:$A$200,0)),"")="Done","READY","WAITING")) -> WAITING | H34: Not Started | J34: ='Read Me'!$B$4+($B34-1)*7 -> 46265 | K34: =J34+6 -> 46271 | L34: Offline is a normal state, not an error
A35: AI-07 | B35: 4 | C35: P1 Commercial | D35: AI/Data | E35: Analytics pipeline | F35: AI-05 | G35: =IF($F35="—","READY",IF(IFERROR(INDEX($H$2:$H$200,MATCH($F35,$A$2:$A$200,0)),"")="Done","READY","WAITING")) -> WAITING | H35: Not Started | J35: ='Read Me'!$B$4+($B35-1)*7 -> 46265 | K35: =J35+6 -> 46271
A36: AI-08 | B36: 4 | C36: P1 Commercial | D36: AI/Data | E36: KPI computation engine | F36: AI-07 | G36: =IF($F36="—","READY",IF(IFERROR(INDEX($H$2:$H$200,MATCH($F36,$A$2:$A$200,0)),"")="Done","READY","WAITING")) -> WAITING | H36: Not Started | J36: ='Read Me'!$B$4+($B36-1)*7 -> 46265 | K36: =J36+6 -> 46271
A37: BE-18 | B37: 5 | C37: P1 Commercial | D37: Backend | E37: Manager APIs + approval hierarchy over territory subtree | F37: BE-13 | G37: =IF($F37="—","READY",IF(IFERROR(INDEX($H$2:$H$200,MATCH($F37,$A$2:$A$200,0)),"")="Done","READY","WAITING")) -> WAITING | H37: Not Started | J37: ='Read Me'!$B$4+($B37-1)*7 -> 46272 | K37: =J37+6 -> 46278
A38: BE-19 | B38: 5 | C38: P1 Commercial | D38: Backend | E38: Content storage and versioning | F38: BE-13 | G38: =IF($F38="—","READY",IF(IFERROR(INDEX($H$2:$H$200,MATCH($F38,$A$2:$A$200,0)),"")="Done","READY","WAITING")) -> WAITING | H38: Not Started | J38: ='Read Me'!$B$4+($B38-1)*7 -> 46272 | K38: =J38+6 -> 46278
A39: FE-11 | B39: 5 | C39: P1 Commercial | D39: Frontend | E39: Field app: digital detailing viewer + finish | F39: FE-10 | G39: =IF($F39="—","READY",IF(IFERROR(INDEX($H$2:$H$200,MATCH($F39,$A$2:$A$200,0)),"")="Done","READY","WAITING")) -> WAITING | H39: Not Started | J39: ='Read Me'!$B$4+($B39-1)*7 -> 46272 | K39: =J39+6 -> 46278
A40: FE-12 | B40: 5 | C40: P1 Commercial | D40: Frontend | E40: TRACKING TRANSPARENCY SCREEN + stop confirmation | F40: FE-11 | G40: =IF($F40="—","READY",IF(IFERROR(INDEX($H$2:$H$200,MATCH($F40,$A$2:$A$200,0)),"")="Done","READY","WAITING")) -> WAITING | H40: Not Started | J40: ='Read Me'!$B$4+($B40-1)*7 -> 46272 | K40: =J40+6 -> 46278 | L40: Main adoption risk - make it reassuring
...

Sheet Timeline
A1: Week | B1: Dates | C1: Phase | D1: Backend | E1: Frontend | F1: AI/Data | G1: Gate
A2: 1 | B2: ='Read Me'!$B$4+(1-1)*7 -> 46244 | C2: P0 Foundations | D2: • Monorepo: Turborepo + pnpm workspaces, strict TS, lint/format • CI/CD: GitHub Actions - typecheck, lint, tests on every PR • Two Supabase projects: Mumbai + US. Same migrations, separate data. • Auth + 9 roles + user_profiles table • PUBLISH packages/core types (contract I1) | E2: • Expo scaffold + Expo Router inside the monorepo • Next.js App Router scaffold • Token pipeline: design-tokens.json to Tailwind + RN theme | F2: • Data model design review with Backend • Analytics event schema definition
A3: 2 | B3: ='Read Me'!$B$4+(2-1)*7 -> 46251 | C3: P0 Foundations | D3: • Commercial schema: orgs, territories, doctors, visits, beat plans, content • Clinical schema namespace + placeholder patients table ONLY • Row-level security policies for all 9 roles • Audit log: DB triggers, append-only, logs reads not just writes • Consent data model - immutable, withdrawal is a new row • MOCK SERVER running with fixtures (contract I2) • Adversarial RLS test suite - 15 attack paths must all fail | E3: • Shell navigation both platforms • Layout primitives + component library wiring • Connect to mock server end to end | F3: • Audit log capture design review • Seed + test data generator (deterministic, re-runnable) | G3: G0: RLS Boundary
A4: 3 | B4: ='Read Me'!$B$4+(3-1)*7 -> 46258 | C4: P1 Commercial | D4: • Doctor, territory, beat-plan APIs • Geo check-in/out API with work-hours enforcement • Aggregation contract I3 published to AI/Data | E4: • Field app: MR day flow shell + beat plan + today • Field app: geo check-in / check-out screens | F4: • Anonymised aggregation service • Suppression logic - any cell under 5 patients renders as dash
A5: 4 | B5: ='Read Me'!$B$4+(4-1)*7 -> 46265 | C5: P1 Commercial | D5: • Offline sync protocol • Sync conflict resolution + queue semantics | E5: • Field app: call report screen • Field app: offline UI + sync state + queue visibility | F5: • Analytics pipeline • KPI computation engine
A6: 5 | B6: ='Read Me'!$B$4+(5-1)*7 -> 46272 | C6: P1 Commercial | D6: • Manager APIs + approval hierarchy over territory subtree • Content storage and versioning | E6: • Field app: digital detailing viewer + finish • TRACKING TRANSPARENCY SCREEN + stop confirmation | F6: • Territory KPI engine • Exception detection logic for manager dashboard
A7: 6 | B7: ='Read Me'!$B$4+(6-1)*7 -> 46279 | C7: P1 Commercial | D7: • API hardening + sync edge cases | E7: • Manager console: shell + exception-first dashboard • Manager console: approvals queue + route review | F7: • Manager dashboard data layer • Dashboard charts + data visualisation | G7: G1: Offline Field Day
A8: 7 | B8: ='Read Me'!$B$4+(7-1)*7 -> 46286 | C8: P2 Clinical | D8: • Clinical schema in full (Prompt 0B) • Consent engine - versioned, clinic-initiated, withdrawable • Patient / diagnosis / prescription APIs | E8: • Patient app: enrolment via clinic code • Patient app: consent flow - multi-step, refusable, withdrawable | F8: • Clinical aggregate layer - anonymised only
A9: 8 | B9: ='Read Me'!$B$4+(8-1)*7 -> 46293 | C9: P2 Clinical | D9: • Diary + vision check APIs • Ophthalmic schedule engine - cadence configurable per market | E9: • Patient app: home / today • Patient app: weekly symptom log • Patient app: dose confirm + reminders | F9: • Diary trend computation • Retention instrumentation
A10: 9 | B10: ='Read Me'!$B$4+(9-1)*7 -> 46300 | C10: P2 Clinical | D10: • AE detection engine + SLA timers computed on insert • Reminder engine - administrative content only | E10: • Patient app: monthly vision check - structured only • Patient app: AE report flow + calm acknowledgement | F10: • LLM gateway scaffold + provider abstraction • Evaluation harness for summary quality • Request/response logging + refusal handling • PUBLISH AI gateway contract I4
A11: 10 | B11: ='Read Me'!$B$4+(10-1)*7 -> 46307 | C11: P2 Clinical | D11: • AE case export with all 4 validity elements • Consent withdrawal handling - AE records must survive | E11: • Doctor console: patient list • Doctor console: patient detail view | F11: • PHI guard - tokenisation and stripping before egress • Prompt design + retrieval index over approved content | G11: G2: Adverse Event Path
A12: 11 | B12: ='Read Me'!$B$4+(11-1)*7 -> 46314 | C12: P3 AI Layer | D12: • PHI tokenisation service for the AI gateway • AI call audit trail - who, what data class, provider, response | E12: • Doctor console: diagnosis entry • Doctor console: prescription entry - brand, form, dose | F12: • Patient history summary with inline citations
A13: 12 | B13: ='Read Me'!$B$4+(12-1)*7 -> 46321 | C13: P3 AI Layer | D13: • External integration work | E13: • Doctor console: ophthalmic monitoring schedule status • AISummaryCard integration | F13: • Visit prep brief • OUTPUT GUARD - hard filter on advice and prediction language • Approved-content retrieval for the field team
A14: 13 | B14: ='Read Me'!$B$4+(13-1)*7 -> 46328 | C14: P3 AI Layer | D14: • Marketing APIs • UCPMP-aware input and sample tracking with value caps | E14: • Gynaecologist referral surface | F14: • Red-team round 1 + full gateway log review | G14: G3: AI Red-Team
A15: 14 | B15: ='Read Me'!$B$4+(14-1)*7 -> 46335 | C15: P4 Mkt/Admin | D15: • Admin APIs + break-glass with mandatory typed reason • Audit log viewer API | E15: • PV console UI - SLA clock is the primary element • Admin console UI - break-glass typed reason before render | F15: • Marketing console + CLM telemetry processing • Content performance analytics + UCPMP reporting | G15: G4: Marketing Boundary
A16: 15 | B16: ='Read Me'!$B$4+(15-1)*7 -> 46342 | C16: P5 Hardening | D16: • Security review + dependency audit + pen test remediation • Backup and restore TESTED (not assumed) + breach runbook | E16: • Accessibility audit + fixes, real screen reader testing • Performance, bundle size, polish | F16: • Red-team round 2 + model cost monitoring + budget alarm • DPIA data-flow map support | G16: G5: Security
A17: 16 | B17: ='Read Me'!$B$4+(16-1)*7 -> 46349 | C17: P6 Pilot | D17: • Pilot ops, monitoring, alerting, on-call | E17: • Pilot bug fixes | F17: • Pilot dashboards + retention measurement | G17: G6: Pilot

Sheet Gates
A1: Gate | B1: Week | C1: Name | D1: Owner | E1: Pass criteria | F1: Warning | G1: Status | H1: Verified by | I1: Date
A2: G0 | B2: 2 | C2: RLS Boundary | D2: Backend | E2: MR / Manager / Marketing tokens denied on clinical data via REST, raw SQL, join, function and view. Audit log rejects UPDATE and DELETE. Break-glass writes audit row BEFORE returning data. | F2: If any test passes when it should fail: STOP. Do not patch in application code. | G2: Not Reached
A3: G1 | B3: 6 | C3: Offline Field Day | D3: Backend + Frontend | E3: One territory runs a full simulated day offline and syncs clean. No lost writes, no duplicates, deterministic conflict resolution. Tracking policy document signed. | G3: Not Reached
A4: G2 | B4: 10 | C4: Adverse Event Path | D4: Backend | E4: Patient logs a vision symptom, flagged in minutes, lands in PV queue with running clock, mock PV officer exports a valid case with all 4 elements. Consent withdrawal does NOT delete the AE record. | F4: IF THIS FAILS, DO NOT PROCEED TO PHASE 3. | G4: Not Reached
A5: G3 | B5: 13 | C5: AI Red-Team | D5: AI/Data | E5: Two independent testers must FAIL to: (a) make AI give clinical advice, (b) surface output to a patient, (c) leak an identifier to the provider, (d) produce an uncited summary. | F5: Not run by the person who built it. | G5: Not Reached
A6: G4 | B6: 14 | C6: Marketing Boundary | D6: Backend | E6: A marketing user attempts to reach patient-level data by every path and fails. Suppression threshold verified on a seeded dataset. | G6: Not Reached
A7: G5 | B7: 15 | C7: Security | D7: Backend | E7: Clean pen test on all high findings. Restore performed from backup, witnessed. | G7: Not Reached
A8: G6 | B8: 16 | C8: Pilot | D8: All | E8: AE path exercised at least once with a real submission. Retention measured, not assumed. | G8: Not Reached
A10: RULE: never start the next phase until the gate passes. The reviewer runs the test personally - never accept a passing report.

Sheet Interfaces
A1: ID | B1: Contract | C1: Owner | D1: Consumers | E1: Due (end of week) | F1: If it slips | G1: Status
A2: I1 | B2: Typed API contract (packages/core types + Zod schemas) | C2: Backend | D2: Frontend, AI/Data | E2: 1 | F2: Frontend cannot start at all | G2: Not Started
A3: I2 | B3: Mock server with realistic fixtures for every endpoint | C3: Backend | D3: Frontend | E3: 2 | F3: Frontend blocked for the whole project. The single highest-value unblocker. | G3: Not Started
A4: I3 | B4: Aggregation contract - what crosses the commercial/clinical boundary, in what shape, with the suppression rule | C4: Backend | D4: AI/Data | E4: 3 | F4: AI/Data cannot build the aggregation service. This is a compliance artifact - get it reviewed. | G4: Not Started
A5: I4 | B5: AI gateway contract - request/response shape, citation format, error and refusal cases | C5: AI/Data | D5: Frontend, Backend | E5: 9 | F5: AISummaryCard cannot be built against a real shape | G5: Not Started
A7: Never change an interface silently. Announce breaking changes in writing before they land.

Sheet Decisions
A1: ID | B1: State | C1: Decision | D1: What it affects | E1: Status / blocking | F1: Owner
A2: O1 | B2: OPEN | C2: Data controller model - pharma-owned vs split vs per-market | D2: Clinical schema, consent engine, whole clinical track | E2: BLOCKING BE-21 (week 7) | F2: Reviewer
A3: O2 | B3: OPEN | C3: Which brand, molecule and legal entity. Elmiron does not exist in India - PPS sells as Comfora, Cystopen, For-IC, Pentossan | D3: Branding, MR content, regulatory owner | E3: BLOCKING design + content | F3: Reviewer
A4: O3 | B4: OPEN | C4: Urologists vs gynaecologists as the detailing audience | D4: Doctor master schema, content strategy, territory design | E4: Needed by week 2 | F4: Reviewer
A5: O4 | B5: OPEN | C5: 'Patient interactions via API' - which system? EMR, WhatsApp, labs, pharmacy? | D5: Integration scope: 2 weeks or 3 months | E5: BLOCKING BE-32 (week 12) | F5: Reviewer
A6: O5 | B6: OPEN | C6: Marketing and sales data scope; source of actual sales data | D6: Phase 4 entirely | E6: Needed by week 4 | F6: Reviewer
A7: O6 | B7: OPEN | C7: Team skill inventory - can AI/Data do SQL and data modelling? | D7: Validity of the whole three-role split | E7: Needed immediately | F7: Reviewer
A8: O7 | B8: OPEN | C8: Existing 'partnering Elmiron project' - never made accessible | D8: Greenfield vs rebuild | E8: Repo confirms greenfield; likely closeable | F8: Reviewer
A9: L1 | B9: LOCKED | C9: AI is non-diagnostic - summarise, organise, retrieve only | D9: No dose suggestions, no risk scores, no ranking | F9: —
A10: L2 | B10: LOCKED | C10: AI is HCP-facing only in v1 - patients see raw data | D10: India TPG prohibition + FDA criterion 3 | F10: —
A11: L3 | B11: LOCKED | C11: LLM provider abstracted, not chosen. Zero-retention DPA required before real data | F11: —
A12: L4 | B12: LOCKED | C12: MR tracking hybrid - continuous during work hours only, hard stop after | D12: Company devices or separated work profile | F12: —
A13: L5 | B13: LOCKED | C13: Web + mobile as two frontends over one shared core | D13: Expo + Next.js, not twelve products | F13: —
A14: L6 | B14: LOCKED | C14: 16 weeks to pilot-ready MVP | F14: —
A15: L7 | B15: LOCKED | C15: Diary is weekly symptom log + monthly vision check, not daily | D15: Retention evidence: median 5.5 days in the wild | F15: —
A16: L8 | B16: LOCKED | C16: AE routing always to a human queue, never AI-triaged | F16: —
A17: L9 | B17: LOCKED | C17: Enrolment is clinic-initiated by the treating doctor | D17: No app-store self-signup for the clinical side | F17: —

Sheet Risks
A1: # | B1: Risk | C1: Likelihood | D1: Impact | E1: Mitigation | F1: Owner | G1: Early warning sign
A2: 1 | B2: Frontend overload from week 7 - patient app and doctor console overlap | C2: High | D2: High | E2: Cut order pre-agreed. AI/Data takes all chart work. Reviewer refuses new screen requests. | F2: Reviewer | G2: FE behind by >3 days at the week-6 checkpoint
A3: 2 | B3: AI/Data invents scope in weeks 3-10 | C3: High | D3: High | E3: Their weeks 1-10 work is specified and gated. Weekly check they are on aggregation, not prototyping a recommender. | F3: Reviewer | G3: Anything appearing that is not in the plan
A4: 3 | B4: Decision O1 unanswered at week 7 | C4: High | D4: High | E4: Escalate now. Clinical schema cannot be built without it. | F4: Reviewer | G4: Still open at end of week 4
A5: 4 | B5: Mock server slips past week 2 | C5: Medium | D5: High | E5: Not optional. A week of blocked frontend costs more than the mock server costs to build. | F5: Backend | G5: Any excuse involving 'the real API is nearly ready'
A6: 5 | B6: Nobody owns QA | C6: High | D6: Medium | E6: Each role tests their own. Reviewer verifies every gate independently - runs the test, never reads the report. | F6: Reviewer | G6: Bugs found at pilot instead of at a gate
A7: 6 | B7: AE volume overwhelms manual PV triage | C7: Medium | D7: High | E7: Structured vision check reduces free text. SLA timers with escalation. Staff before launch, not after. | F7: Backend | G7: AE queue depth at pilot
A8: 7 | B8: Backend bottleneck weeks 7-9 - clinical schema, consent and AE engine all land together | C8: Medium | D8: High | E8: Densest backend stretch in the project. Consider moving the reminder engine to week 10. | F8: Backend | G8: BE behind at the week-8 checkpoint
A9: 8 | B9: PHI leaks to the LLM provider | C9: Medium | D9: High | E9: Gateway with tokenisation. Zero-retention DPA signed before real data. Log review at Gate 3. | F9: AI/Data | G9: Any identifier in a provider payload
A10: 9 | B10: RBAC enforced in UI only, not at the database | C10: Medium | D10: Critical | E10: Gate 0 is an automated adversarial test, not a code read. | F10: Backend | G10: Empty results where permission-denied is expected
A11: 10 | B11: Patient retention collapses | C11: High | D11: High | E11: Weekly not daily. Clinic enrolment. Human follow-up budgeted. Measure at pilot, do not assume. | F11: AI/Data | G11: Retention instrumentation at week 8
A12: 11 | B12: Wrong drug, brand or legal entity (decision O2) | C12: High | D12: High | E12: Answer O2 in week 1 | F12: Reviewer | G12: Still open at end of week 2
A13: 12 | B13: Bus factor of 1 on every role | C13: High | D13: Medium | E13: PROJECT-OVERVIEW.md appended every phase, not at the end. | F13: All | G13: One person off sick in week 9

Sheet Cut Order
A1: CUT ORDER - agreed in advance
A2: When the schedule slips, cut from the top. Never negotiate this in the moment.
A4: Order | B4: Cut this | C4: Consequence
A5: 1 | B5: Marketing console | C5: Manual process for the pilot
A6: 2 | B6: Gynaecologist referral surface | C6: Deferred to phase 2
A7: 3 | B7: Admin console polish | C7: Functional but plain
A8: 4 | B8: PV console polish | C8: Functional but plain. The SLA clock stays.
A9: 5 | B9: Visit prep brief | C9: History summary alone is enough for the pilot
A10: 6 | B10: Field app: expenses, training, certification | C10: Manual for the pilot
A11: 7 | B11: Patient app: my-visits, help screens | C11: Deferred
A13: NEVER CUT
B14: Phase 0 in any form
B15: The Phase 2 adverse-event gate
B16: Row-level security
B17: The audit log
B18: The AI output guard
B19: Patient-app accessibility
B20: The tracking transparency screen
A22: These six are the difference between a product and a liability.
